creating web directory ./results/ellen_dwt_uresnet2_3_512n1000_1121_2/test_latest
processing (0000)-th image... ['/home/guest1/ellen_data/UKB_quality_data2_combined/input_20220623_512_n1000/testA/0001.jpg']
/home/guest1/.conda/envs/ellen/lib/python3.7/site-packages/torch/nn/functional.py:3635: UserWarning: Default upsampling behavior when mode=bilinear is changed to align_corners=False since 0.4.0. Please specify align_corners=True if the old behavior is desired. See the documentation of nn.Upsample for details.
  "See the documentation of nn.Upsample for details.".format(mode)
processing (0005)-th image... ['/home/guest1/ellen_data/UKB_quality_data2_combined/input_20220623_512_n1000/testA/0006.jpg']
processing (0010)-th image... ['/home/guest1/ellen_data/UKB_quality_data2_combined/input_20220623_512_n1000/testA/0011.jpg']
processing (0015)-th image... ['/home/guest1/ellen_data/UKB_quality_data2_combined/input_20220623_512_n1000/testA/0016.jpg']
processing (0020)-th image... ['/home/guest1/ellen_data/UKB_quality_data2_combined/input_20220623_512_n1000/testA/0021.jpg']
processing (0025)-th image... ['/home/guest1/ellen_data/UKB_quality_data2_combined/input_20220623_512_n1000/testA/0026.jpg']
Traceback (most recent call last):
  File "/home/guest1/.conda/envs/ellen/lib/python3.7/site-packages/PIL/ImageFile.py", line 504, in _save
    fh = fp.fileno()
AttributeError: '_idat' object has no attribute 'fileno'
During handling of the above exception, another exception occurred:
Traceback (most recent call last):
  File "test.py", line 112, in <module>
    save_images(webpage, visuals, img_path, aspect_ratio=opt.aspect_ratio, width=opt.display_winsize, use_wandb=opt.use_wandb)
  File "/home/guest1/ellen_code/pytorch-CycleGAN-and-pix2pix_ellen/util/visualizer.py", line 44, in save_images
    util.save_image(im, save_path, aspect_ratio=aspect_ratio)
  File "/home/guest1/ellen_code/pytorch-CycleGAN-and-pix2pix_ellen/util/util.py", line 66, in save_image
    image_pil.save(image_path)
  File "/home/guest1/.conda/envs/ellen/lib/python3.7/site-packages/PIL/Image.py", line 2240, in save
    save_handler(self, fp, filename)
  File "/home/guest1/.conda/envs/ellen/lib/python3.7/site-packages/PIL/PngImagePlugin.py", line 1348, in _save
    ImageFile._save(im, _idat(fp, chunk), [("zip", (0, 0) + im.size, 0, rawmode)])
  File "/home/guest1/.conda/envs/ellen/lib/python3.7/site-packages/PIL/ImageFile.py", line 519, in _save
    fp.write(d)
  File "/home/guest1/.conda/envs/ellen/lib/python3.7/site-packages/PIL/PngImagePlugin.py", line 1044, in write
    self.chunk(self.fp, b"IDAT", data)
  File "/home/guest1/.conda/envs/ellen/lib/python3.7/site-packages/PIL/PngImagePlugin.py", line 1031, in putchunk
    fp.write(data)
OSError: [Errno 28] No space left on device
processing (0030)-th image... ['/home/guest1/ellen_data/UKB_quality_data2_combined/input_20220623_512_n1000/testA/0031.jpg']